#VRML_SIM R2023b utf8
# license: Copyright Cyberbotics Ltd. Licensed for use only with Webots.
# license url: https://cyberbotics.com/webots_assets_license
# documentation url: https://webots.cloud/run?url=https://github.com/HyperDroids10015/FTCSimulator/main/WebotsProjects/CENTERSTAGE/protos/GoBildaRi3D_2023.proto
# keywords: robot/wheeled
# This is the arena for the FTC CENTERSTAGE season

EXTERNPROTO "https://raw.githubusercontent.com/cyberbotics/webots/R2023b/projects/objects/floors/protos/RectangleArena.proto"
EXTERNPROTO "Backdrop.proto"
EXTERNPROTO "Pixel.proto"

PROTO CenterStageArena [
]
{
  Group {
    children [
      RectangleArena {
        floorSize 3.584 3.584
        floorTileSize 3.584 3.584
        floorAppearance PBRAppearance {
          baseColor 0.776471 0.776471 0.776471
          baseColorMap ImageTexture {
            url [
              "field.png"
            ]
            repeatS FALSE
            repeatT FALSE
          }
          roughness 1
          metalness 0
        }
        wallThickness 0.0267
        wallHeight 0.3
        wallAppearance PBRAppearance {
          transparency 0.9
          roughness 1
          metalness 0
        }
      }
      Backdrop {
        translation -0.9 1.535 0
        name "Blue Backdrop"
      }
      Backdrop {
        translation 0.9 1.535 0
        name "Red Backdrop"
      }
      DEF Truss Group {
        children [
          Solid {
            translation -0.6 -0.0925 0.287468
            rotation 1 0 0 0.436332313
            children [
              DEF TRUSS Shape {
                appearance PBRAppearance {
                  roughness 1
                  metalness 0
                }
                geometry Box {
                  size 0.0254 0.0254 0.6096
                }
              }
            ]
            name "Truss Leg 1"
            boundingObject USE TRUSS
            locked TRUE
          }
          Solid {
            translation -0.6 -0.510293 0.287468
            rotation 1 0 0 -0.436332313
            children [
              USE TRUSS
            ]
            name "Truss Leg 2"
            boundingObject USE TRUSS
            locked TRUE
          }
          Solid {
            translation -1.2 -0.0925 0.287468
            rotation 1 0 0 0.436332313
            children [
              USE TRUSS
            ]
            name "Truss Leg 3"
            boundingObject USE TRUSS
            locked TRUE
          }
          Solid {
            translation -1.2 -0.510293 0.287468
            rotation 1 0 0 -0.436332313
            children [
              USE TRUSS
            ]
            name "Truss Leg 4"
            boundingObject USE TRUSS
            locked TRUE
          }
          Solid {
            translation -1.7793 -0.0925 0.287468
            rotation 1 0 0 0.436332313
            children [
              USE TRUSS
            ]
            name "Truss Leg 5"
            boundingObject USE TRUSS
            locked TRUE
          }
          Solid {
            translation -1.7793 -0.510293 0.287468
            rotation 1 0 0 -0.436332313
            children [
              USE TRUSS
            ]
            name "Truss Leg 6"
            boundingObject USE TRUSS
            locked TRUE
          }
          Solid {
            translation 0.6 -0.0925 0.287468
            rotation 1 0 0 0.436332313
            children [
              USE TRUSS
            ]
            name "Truss Leg 7"
            boundingObject USE TRUSS
            locked TRUE
          }
          Solid {
            translation 0.6 -0.510293 0.287468
            rotation 1 0 0 -0.436332313
            children [
              USE TRUSS
            ]
            name "Truss Leg 8"
            boundingObject USE TRUSS
            locked TRUE
          }
          Solid {
            translation 1.2 -0.0925 0.287468
            rotation 1 0 0 0.436332313
            children [
              USE TRUSS
            ]
            name "Truss Leg 9"
            boundingObject USE TRUSS
            locked TRUE
          }
          Solid {
            translation 1.2 -0.510293 0.287468
            rotation 1 0 0 -0.436332313
            children [
              USE TRUSS
            ]
            name "Truss Leg 10"
            boundingObject USE TRUSS
            locked TRUE
          }
          Solid {
            translation 1.7793 -0.0925 0.287468
            rotation 1 0 0 0.436332313
            children [
              USE TRUSS
            ]
            name "Truss Leg 11"
            boundingObject USE TRUSS
            locked TRUE
          }
          Solid {
            translation 1.7793 -0.510293 0.287468
            rotation 1 0 0 -0.436332313
            children [
              USE TRUSS
            ]
            name "Truss Leg 12"
            boundingObject USE TRUSS
            locked TRUE
          }
          Solid {
            translation -0.9 -0.269646 0.575205
            rotation 0 1 0 1.5707963267948966
            children [
              DEF BLUEBAR Shape {
                appearance PBRAppearance {
                  baseColor 0 0 1
                  roughness 1
                  metalness 0
                }
                geometry Cylinder {
                  height 0.6223
                  radius 0.016675
                }
              }
            ]
            name "Blue Hanging Bar 1"
            boundingObject USE BLUEBAR
            locked TRUE
          }
          Solid {
            translation -1.5 -0.333146 0.575205
            rotation 0 1 0 1.5707963267948966
            children [
              USE BLUEBAR
            ]
            name "Blue Hanging Bar 2"
            boundingObject USE BLUEBAR
            locked TRUE
          }
          Solid {
            translation 0.9 -0.269646 0.575205
            rotation 0 1 0 1.5707963267948966
            children [
              DEF REDBAR Shape {
                appearance PBRAppearance {
                  baseColor 1 0 0
                  roughness 1
                  metalness 0
                }
                geometry Cylinder {
                  height 0.6223
                  radius 0.016675
                }
              }
            ]
            name "Red Hanging Bar 1"
            boundingObject USE REDBAR
            locked TRUE
          }
          Solid {
            translation 1.5 -0.333146 0.575205
            rotation 0 1 0 1.5707963267948966
            children [
              USE REDBAR
            ]
            name "Red Hanging Bar 2"
            boundingObject USE REDBAR
            locked TRUE
          }
          Solid {
            translation -0.9 -0.502551 0.368935
            rotation 0 1 0 1.5707963267948966
            children [
              DEF YELLOWBAR Shape {
                appearance PBRAppearance {
                  baseColor 1 1 0
                  roughness 1
                  metalness 0
                }
                geometry Cylinder {
                  height 0.6223
                  radius 0.013335
                }
              }
            ]
            name "Height Limiter 1"
            boundingObject USE REDBAR
            locked TRUE
          }
          Solid {
            translation -1.5 -0.100266 0.368935
            rotation 0 1 0 1.5707963267948966
            children [
              USE YELLOWBAR
            ]
            name "Height Limiter 2"
            boundingObject USE REDBAR
            locked TRUE
          }
          Solid {
            translation 0.9 -0.502551 0.368935
            rotation 0 1 0 1.5707963267948966
            children [
              USE YELLOWBAR
            ]
            name "Height Limiter 3"
            boundingObject USE REDBAR
            locked TRUE
          }
          Solid {
            translation 1.5 -0.100266 0.368935
            rotation 0 1 0 1.5707963267948966
            children [
              USE YELLOWBAR
            ]
            name "Height Limiter 4"
            boundingObject USE REDBAR
            locked TRUE
          }
        ]
      }
      Solid {
        translation 0 -0.269646 0.575205
        rotation 0 1 0 1.5707963267948966
        children [
          DEF YELLOWLONGBAR Shape {
            appearance PBRAppearance {
              baseColor 1 1 0
              roughness 1
              metalness 0
            }
            geometry Cylinder {
              height 1.2446
              radius 0.013335
            }
          }
          HingeJoint {
            jointParameters HingeJointParameters {
              position 0.001
              axis 0 0 1
              minStop 0.001
              maxStop 1.0
            }
            endPoint Solid {
              translation 0.24549013589613808 0.18609682073236955 0
              rotation 0 0 -1 0
              children [
                USE YELLOWLONGBAR
              ]
              boundingObject USE YELLOWLONGBAR
              physics Physics {
                density -1
                mass 1
              }
              linearVelocity 0 0 0
              angularVelocity 0 0 0
            }
          }
        ]
        name "Stage Door"
        locked TRUE
      }
    ]
  }
}