#VRML_SIM R2023b utf8
# license: Copyright Cyberbotics Ltd. Licensed for use only with Webots.
# license url: https://cyberbotics.com/webots_assets_license
# tags: hidden
# omnidirectionnal wheels with 2D coulomb friction

EXTERNPROTO "InteriorWheelMesh.proto"
EXTERNPROTO "SubWheelMesh.proto"

PROTO InteriorWheel [
  field SFVec3f translation 0 0 0
  field SFVec3f anchor 0 0 0
  field SFString name "wheel"
  field SFString sensorName "wheel_sensor"
]
{
  HingeJoint {
    device [
      RotationalMotor {
        name IS name
        maxVelocity 32.67
      }
      PositionSensor {
        name IS sensorName
      }
    ]
    jointParameters HingeJointParameters {
      axis 0 1 0
      anchor IS anchor
    }
    endPoint DEF WHEEL_SOLID Solid {
      translation IS translation
      children [
        InteriorWheelMesh {
        }
        Pose {
          translation 0.03798935 0 0.01234349
          rotation 0.9510565 0 0.309017 0.7853982
          children [
            SubWheelMesh {
            }
          ]
        }
        Pose {
          translation 0.02347871 0 0.03231568
          rotation 0.5877852 0 0.809017 0.7853982
          children [
            SubWheelMesh {
            }
          ]
        }
        Pose {
          translation 0 0 0.03994437
          rotation 0 0 1 0.7853982
          children [
            SubWheelMesh {
            }
          ]
        }
        Pose {
          translation -0.02347871 0 0.03231568
          rotation -0.5877852 0 0.809017 0.7853982
          children [
            SubWheelMesh {
            }
          ]
        }
        Pose {
          translation -0.03798935 0 0.01234349
          rotation -0.9510565 0 0.309017 0.7853982
          children [
            SubWheelMesh {
            }
          ]
        }
        Pose {
          translation -0.03798935 0 -0.01234349
          rotation -0.9510565 0 -0.309017 0.7853982
          children [
            SubWheelMesh {
            }
          ]
        }
        Pose {
          translation -0.02347871 0 -0.03231568
          rotation -0.5877852 0 -0.809017 0.7853982
          children [
            SubWheelMesh {
            }
          ]
        }
        Pose {
          translation 0 0 -0.03994437
          rotation 0 0 -1 0.7853982
          children [
            SubWheelMesh {
            }
          ]
        }
        Pose {
          translation 0.02347871 0 -0.03231568
          rotation 0.5877852 0 -0.809017 0.7853982
          children [
            SubWheelMesh {
            }
          ]
        }
        Pose {
          translation 0.03798935 0 -0.01234349
          rotation 0.9510565 0 -0.309017 0.7853982
          children [
            SubWheelMesh {
            }
          ]
        }
      ]
      name IS name
      contactMaterial "InteriorWheelMat"
      boundingObject Pose {
        rotation 1 0 0 -1.5708
        children [
          Cylinder {
            height 0.038
            radius 0.048
            subdivision 24
          }
        ]
      }
      physics Physics {
        density -1
        mass 0.207
      }
    }
  }
}
